[2019-08-01 11:30:51 +0000] [205] [CRITICAL] WORKER TIMEOUT (pid:212)
[2019-08-01 11:37:28 +0000] [205] [CRITICAL] WORKER TIMEOUT (pid:211)
2019-08-01 11:37:50,629 DB error: Unique user not found.
2019-08-01 11:37:50,631 Exception during reset or similar
Traceback (most recent call last):
  File "/home/eddjou/.local/lib/python2.7/site-packages/sqlalchemy/pool/base.py", line 680, in _finalize_fairy
    fairy._reset(pool)
  File "/home/eddjou/.local/lib/python2.7/site-packages/sqlalchemy/pool/base.py", line 867, in _reset
    pool._dialect.do_rollback(self)
  File "/home/eddjou/.local/lib/python2.7/site-packages/sqlalchemy/engine/default.py", line 500, in do_rollback
    dbapi_connection.rollback()
OperationalError: cannot rollback - no transaction is active
[2019-08-01 11:43:31 +0000] [205] [CRITICAL] WORKER TIMEOUT (pid:210)
2019-08-01 13:01:48,436 hit_assign_worker_id_not_set_in_exp (1003) {'assignmentId': [u'debug47NNT1'], 'workerId': [u'debugSLGI6P'], 'hitId': [u'debug6H779Q']}
2019-08-01 13:02:02,360 hit_assign_worker_id_not_set_in_exp (1003) {'assignmentId': [u'debug47NNT1'], 'workerId': [u'debugSLGI6P'], 'hitId': [u'debug6H779Q']}
2019-08-01 13:02:37,889 Exception on /sync/debugSLGI6P:debug47NNT1 [PUT]
Traceback (most recent call last):
  File "/home/eddjou/.local/lib/python2.7/site-packages/flask/app.py", line 2311, in wsgi_app
    response = self.full_dispatch_request()
  File "/home/eddjou/.local/lib/python2.7/site-packages/flask/app.py", line 1834, in full_dispatch_request
    rv = self.handle_user_exception(e)
  File "/home/eddjou/.local/lib/python2.7/site-packages/flask/app.py", line 1737, in handle_user_exception
    reraise(exc_type, exc_value, tb)
  File "/home/eddjou/.local/lib/python2.7/site-packages/flask/app.py", line 1832, in full_dispatch_request
    rv = self.dispatch_request()
  File "/home/eddjou/.local/lib/python2.7/site-packages/flask/app.py", line 1818, in dispatch_request
    return self.view_functions[rule.endpoint](**req.view_args)
  File "/home/eddjou/.local/lib/python2.7/site-packages/psiturk/experiment.py", line 591, in update
    db_session.commit()
  File "/home/eddjou/.local/lib/python2.7/site-packages/sqlalchemy/orm/scoping.py", line 162, in do
    return getattr(self.registry(), name)(*args, **kwargs)
  File "/home/eddjou/.local/lib/python2.7/site-packages/sqlalchemy/orm/session.py", line 1027, in commit
    self.transaction.commit()
  File "/home/eddjou/.local/lib/python2.7/site-packages/sqlalchemy/orm/session.py", line 498, in commit
    t[1].commit()
  File "/home/eddjou/.local/lib/python2.7/site-packages/sqlalchemy/engine/base.py", line 1716, in commit
    self._do_commit()
  File "/home/eddjou/.local/lib/python2.7/site-packages/sqlalchemy/engine/base.py", line 1747, in _do_commit
    self.connection._commit_impl()
  File "/home/eddjou/.local/lib/python2.7/site-packages/sqlalchemy/engine/base.py", line 763, in _commit_impl
    self._handle_dbapi_exception(e, None, None, None, None)
  File "/home/eddjou/.local/lib/python2.7/site-packages/sqlalchemy/engine/base.py", line 1466, in _handle_dbapi_exception
    util.raise_from_cause(sqlalchemy_exception, exc_info)
  File "/home/eddjou/.local/lib/python2.7/site-packages/sqlalchemy/util/compat.py", line 399, in raise_from_cause
    reraise(type(exception), exception, tb=exc_tb, cause=cause)
  File "/home/eddjou/.local/lib/python2.7/site-packages/sqlalchemy/engine/base.py", line 761, in _commit_impl
    self.engine.dialect.do_commit(self.connection)
  File "/home/eddjou/.local/lib/python2.7/site-packages/sqlalchemy/engine/default.py", line 503, in do_commit
    dbapi_connection.commit()
OperationalError: (sqlite3.OperationalError) disk I/O error
(Background on this error at: http://sqlalche.me/e/e3q8)
2019-08-01 13:02:37,910 Exception during reset or similar
Traceback (most recent call last):
  File "/home/eddjou/.local/lib/python2.7/site-packages/sqlalchemy/pool/base.py", line 680, in _finalize_fairy
    fairy._reset(pool)
  File "/home/eddjou/.local/lib/python2.7/site-packages/sqlalchemy/pool/base.py", line 867, in _reset
    pool._dialect.do_rollback(self)
  File "/home/eddjou/.local/lib/python2.7/site-packages/sqlalchemy/engine/default.py", line 500, in do_rollback
    dbapi_connection.rollback()
OperationalError: cannot rollback - no transaction is active
2019-08-02 11:09:19,225 DB error: Unique user not found.
2019-08-02 11:09:19,226 Exception during reset or similar
Traceback (most recent call last):
  File "/home/eddjou/.local/lib/python2.7/site-packages/sqlalchemy/pool/base.py", line 680, in _finalize_fairy
    fairy._reset(pool)
  File "/home/eddjou/.local/lib/python2.7/site-packages/sqlalchemy/pool/base.py", line 867, in _reset
    pool._dialect.do_rollback(self)
  File "/home/eddjou/.local/lib/python2.7/site-packages/sqlalchemy/engine/default.py", line 500, in do_rollback
    dbapi_connection.rollback()
OperationalError: cannot rollback - no transaction is active
2019-08-02 11:13:16,450 Exception on /sync/debugATCNKI:debugP82OUV [PUT]
Traceback (most recent call last):
  File "/home/eddjou/.local/lib/python2.7/site-packages/flask/app.py", line 2311, in wsgi_app
    response = self.full_dispatch_request()
  File "/home/eddjou/.local/lib/python2.7/site-packages/flask/app.py", line 1834, in full_dispatch_request
    rv = self.handle_user_exception(e)
  File "/home/eddjou/.local/lib/python2.7/site-packages/flask/app.py", line 1737, in handle_user_exception
    reraise(exc_type, exc_value, tb)
  File "/home/eddjou/.local/lib/python2.7/site-packages/flask/app.py", line 1832, in full_dispatch_request
    rv = self.dispatch_request()
  File "/home/eddjou/.local/lib/python2.7/site-packages/flask/app.py", line 1818, in dispatch_request
    return self.view_functions[rule.endpoint](**req.view_args)
  File "/home/eddjou/.local/lib/python2.7/site-packages/psiturk/experiment.py", line 591, in update
    db_session.commit()
  File "/home/eddjou/.local/lib/python2.7/site-packages/sqlalchemy/orm/scoping.py", line 162, in do
    return getattr(self.registry(), name)(*args, **kwargs)
  File "/home/eddjou/.local/lib/python2.7/site-packages/sqlalchemy/orm/session.py", line 1027, in commit
    self.transaction.commit()
  File "/home/eddjou/.local/lib/python2.7/site-packages/sqlalchemy/orm/session.py", line 498, in commit
    t[1].commit()
  File "/home/eddjou/.local/lib/python2.7/site-packages/sqlalchemy/engine/base.py", line 1716, in commit
    self._do_commit()
  File "/home/eddjou/.local/lib/python2.7/site-packages/sqlalchemy/engine/base.py", line 1747, in _do_commit
    self.connection._commit_impl()
  File "/home/eddjou/.local/lib/python2.7/site-packages/sqlalchemy/engine/base.py", line 763, in _commit_impl
    self._handle_dbapi_exception(e, None, None, None, None)
  File "/home/eddjou/.local/lib/python2.7/site-packages/sqlalchemy/engine/base.py", line 1466, in _handle_dbapi_exception
    util.raise_from_cause(sqlalchemy_exception, exc_info)
  File "/home/eddjou/.local/lib/python2.7/site-packages/sqlalchemy/util/compat.py", line 399, in raise_from_cause
    reraise(type(exception), exception, tb=exc_tb, cause=cause)
  File "/home/eddjou/.local/lib/python2.7/site-packages/sqlalchemy/engine/base.py", line 761, in _commit_impl
    self.engine.dialect.do_commit(self.connection)
  File "/home/eddjou/.local/lib/python2.7/site-packages/sqlalchemy/engine/default.py", line 503, in do_commit
    dbapi_connection.commit()
OperationalError: (sqlite3.OperationalError) disk I/O error
(Background on this error at: http://sqlalche.me/e/e3q8)
2019-08-02 11:13:16,461 Exception during reset or similar
Traceback (most recent call last):
  File "/home/eddjou/.local/lib/python2.7/site-packages/sqlalchemy/pool/base.py", line 680, in _finalize_fairy
    fairy._reset(pool)
  File "/home/eddjou/.local/lib/python2.7/site-packages/sqlalchemy/pool/base.py", line 867, in _reset
    pool._dialect.do_rollback(self)
  File "/home/eddjou/.local/lib/python2.7/site-packages/sqlalchemy/engine/default.py", line 500, in do_rollback
    dbapi_connection.rollback()
OperationalError: cannot rollback - no transaction is active
[2019-08-02 11:30:20 +0000] [40] [CRITICAL] WORKER TIMEOUT (pid:53)
2019-08-02 11:38:03,553 DB error: Unique user not found.
2019-08-02 11:38:03,555 Exception during reset or similar
Traceback (most recent call last):
  File "/home/eddjou/.local/lib/python2.7/site-packages/sqlalchemy/pool/base.py", line 680, in _finalize_fairy
    fairy._reset(pool)
  File "/home/eddjou/.local/lib/python2.7/site-packages/sqlalchemy/pool/base.py", line 867, in _reset
    pool._dialect.do_rollback(self)
  File "/home/eddjou/.local/lib/python2.7/site-packages/sqlalchemy/engine/default.py", line 500, in do_rollback
    dbapi_connection.rollback()
OperationalError: cannot rollback - no transaction is active
[2019-08-02 11:38:34 +0000] [40] [CRITICAL] WORKER TIMEOUT (pid:83)
2019-08-02 11:46:33,234 DB error: Unique user not found.
2019-08-02 11:46:33,236 Exception during reset or similar
Traceback (most recent call last):
  File "/home/eddjou/.local/lib/python2.7/site-packages/sqlalchemy/pool/base.py", line 680, in _finalize_fairy
    fairy._reset(pool)
  File "/home/eddjou/.local/lib/python2.7/site-packages/sqlalchemy/pool/base.py", line 867, in _reset
    pool._dialect.do_rollback(self)
  File "/home/eddjou/.local/lib/python2.7/site-packages/sqlalchemy/engine/default.py", line 500, in do_rollback
    dbapi_connection.rollback()
OperationalError: cannot rollback - no transaction is active
2019-08-02 17:31:14,852 Exception on /sync/debug57J7KW:debugU4WADY [PUT]
Traceback (most recent call last):
  File "/home/eddjou/.local/lib/python2.7/site-packages/flask/app.py", line 2311, in wsgi_app
    response = self.full_dispatch_request()
  File "/home/eddjou/.local/lib/python2.7/site-packages/flask/app.py", line 1834, in full_dispatch_request
    rv = self.handle_user_exception(e)
  File "/home/eddjou/.local/lib/python2.7/site-packages/flask/app.py", line 1737, in handle_user_exception
    reraise(exc_type, exc_value, tb)
  File "/home/eddjou/.local/lib/python2.7/site-packages/flask/app.py", line 1832, in full_dispatch_request
    rv = self.dispatch_request()
  File "/home/eddjou/.local/lib/python2.7/site-packages/flask/app.py", line 1818, in dispatch_request
    return self.view_functions[rule.endpoint](**req.view_args)
  File "/home/eddjou/.local/lib/python2.7/site-packages/psiturk/experiment.py", line 591, in update
    db_session.commit()
  File "/home/eddjou/.local/lib/python2.7/site-packages/sqlalchemy/orm/scoping.py", line 162, in do
    return getattr(self.registry(), name)(*args, **kwargs)
  File "/home/eddjou/.local/lib/python2.7/site-packages/sqlalchemy/orm/session.py", line 1027, in commit
    self.transaction.commit()
  File "/home/eddjou/.local/lib/python2.7/site-packages/sqlalchemy/orm/session.py", line 498, in commit
    t[1].commit()
  File "/home/eddjou/.local/lib/python2.7/site-packages/sqlalchemy/engine/base.py", line 1716, in commit
    self._do_commit()
  File "/home/eddjou/.local/lib/python2.7/site-packages/sqlalchemy/engine/base.py", line 1747, in _do_commit
    self.connection._commit_impl()
  File "/home/eddjou/.local/lib/python2.7/site-packages/sqlalchemy/engine/base.py", line 763, in _commit_impl
    self._handle_dbapi_exception(e, None, None, None, None)
  File "/home/eddjou/.local/lib/python2.7/site-packages/sqlalchemy/engine/base.py", line 1466, in _handle_dbapi_exception
    util.raise_from_cause(sqlalchemy_exception, exc_info)
  File "/home/eddjou/.local/lib/python2.7/site-packages/sqlalchemy/util/compat.py", line 399, in raise_from_cause
    reraise(type(exception), exception, tb=exc_tb, cause=cause)
  File "/home/eddjou/.local/lib/python2.7/site-packages/sqlalchemy/engine/base.py", line 761, in _commit_impl
    self.engine.dialect.do_commit(self.connection)
  File "/home/eddjou/.local/lib/python2.7/site-packages/sqlalchemy/engine/default.py", line 503, in do_commit
    dbapi_connection.commit()
OperationalError: (sqlite3.OperationalError) disk I/O error
(Background on this error at: http://sqlalche.me/e/e3q8)
2019-08-02 17:31:14,869 Exception during reset or similar
Traceback (most recent call last):
  File "/home/eddjou/.local/lib/python2.7/site-packages/sqlalchemy/pool/base.py", line 680, in _finalize_fairy
    fairy._reset(pool)
  File "/home/eddjou/.local/lib/python2.7/site-packages/sqlalchemy/pool/base.py", line 867, in _reset
    pool._dialect.do_rollback(self)
  File "/home/eddjou/.local/lib/python2.7/site-packages/sqlalchemy/engine/default.py", line 500, in do_rollback
    dbapi_connection.rollback()
OperationalError: cannot rollback - no transaction is active
2019-08-05 08:24:27,753 Exception on /static/js/task.js [GET]
Traceback (most recent call last):
  File "/home/eddjou/.local/lib/python2.7/site-packages/flask/app.py", line 2311, in wsgi_app
    response = self.full_dispatch_request()
  File "/home/eddjou/.local/lib/python2.7/site-packages/flask/app.py", line 1834, in full_dispatch_request
    rv = self.handle_user_exception(e)
  File "/home/eddjou/.local/lib/python2.7/site-packages/flask/app.py", line 1737, in handle_user_exception
    reraise(exc_type, exc_value, tb)
  File "/home/eddjou/.local/lib/python2.7/site-packages/flask/app.py", line 1832, in full_dispatch_request
    rv = self.dispatch_request()
  File "/home/eddjou/.local/lib/python2.7/site-packages/flask/app.py", line 1818, in dispatch_request
    return self.view_functions[rule.endpoint](**req.view_args)
  File "/home/eddjou/.local/lib/python2.7/site-packages/flask/helpers.py", line 983, in send_static_file
    cache_timeout=cache_timeout)
  File "/home/eddjou/.local/lib/python2.7/site-packages/flask/helpers.py", line 720, in send_from_directory
    return send_file(filename, **options)
  File "/home/eddjou/.local/lib/python2.7/site-packages/flask/helpers.py", line 595, in send_file
    file = open(filename, 'rb')
IOError: [Errno 13] Permission denied: u'/home/eddjou/exp-psiturk-example/static/js/task.js'
2019-08-05 08:24:28,114 Exception on /static/js/task.js [GET]
Traceback (most recent call last):
  File "/home/eddjou/.local/lib/python2.7/site-packages/flask/app.py", line 2311, in wsgi_app
    response = self.full_dispatch_request()
  File "/home/eddjou/.local/lib/python2.7/site-packages/flask/app.py", line 1834, in full_dispatch_request
    rv = self.handle_user_exception(e)
  File "/home/eddjou/.local/lib/python2.7/site-packages/flask/app.py", line 1737, in handle_user_exception
    reraise(exc_type, exc_value, tb)
  File "/home/eddjou/.local/lib/python2.7/site-packages/flask/app.py", line 1832, in full_dispatch_request
    rv = self.dispatch_request()
  File "/home/eddjou/.local/lib/python2.7/site-packages/flask/app.py", line 1818, in dispatch_request
    return self.view_functions[rule.endpoint](**req.view_args)
  File "/home/eddjou/.local/lib/python2.7/site-packages/flask/helpers.py", line 983, in send_static_file
    cache_timeout=cache_timeout)
  File "/home/eddjou/.local/lib/python2.7/site-packages/flask/helpers.py", line 720, in send_from_directory
    return send_file(filename, **options)
  File "/home/eddjou/.local/lib/python2.7/site-packages/flask/helpers.py", line 595, in send_file
    file = open(filename, 'rb')
IOError: [Errno 13] Permission denied: u'/home/eddjou/exp-psiturk-example/static/js/task.js'
2019-08-05 08:24:43,516 Exception on /static/js/task.js [GET]
Traceback (most recent call last):
  File "/home/eddjou/.local/lib/python2.7/site-packages/flask/app.py", line 2311, in wsgi_app
    response = self.full_dispatch_request()
  File "/home/eddjou/.local/lib/python2.7/site-packages/flask/app.py", line 1834, in full_dispatch_request
    rv = self.handle_user_exception(e)
  File "/home/eddjou/.local/lib/python2.7/site-packages/flask/app.py", line 1737, in handle_user_exception
    reraise(exc_type, exc_value, tb)
  File "/home/eddjou/.local/lib/python2.7/site-packages/flask/app.py", line 1832, in full_dispatch_request
    rv = self.dispatch_request()
  File "/home/eddjou/.local/lib/python2.7/site-packages/flask/app.py", line 1818, in dispatch_request
    return self.view_functions[rule.endpoint](**req.view_args)
  File "/home/eddjou/.local/lib/python2.7/site-packages/flask/helpers.py", line 983, in send_static_file
    cache_timeout=cache_timeout)
  File "/home/eddjou/.local/lib/python2.7/site-packages/flask/helpers.py", line 720, in send_from_directory
    return send_file(filename, **options)
  File "/home/eddjou/.local/lib/python2.7/site-packages/flask/helpers.py", line 595, in send_file
    file = open(filename, 'rb')
IOError: [Errno 13] Permission denied: u'/home/eddjou/exp-psiturk-example/static/js/task.js'
2019-08-05 08:24:43,878 Exception on /static/js/task.js [GET]
Traceback (most recent call last):
  File "/home/eddjou/.local/lib/python2.7/site-packages/flask/app.py", line 2311, in wsgi_app
    response = self.full_dispatch_request()
  File "/home/eddjou/.local/lib/python2.7/site-packages/flask/app.py", line 1834, in full_dispatch_request
    rv = self.handle_user_exception(e)
  File "/home/eddjou/.local/lib/python2.7/site-packages/flask/app.py", line 1737, in handle_user_exception
    reraise(exc_type, exc_value, tb)
  File "/home/eddjou/.local/lib/python2.7/site-packages/flask/app.py", line 1832, in full_dispatch_request
    rv = self.dispatch_request()
  File "/home/eddjou/.local/lib/python2.7/site-packages/flask/app.py", line 1818, in dispatch_request
    return self.view_functions[rule.endpoint](**req.view_args)
  File "/home/eddjou/.local/lib/python2.7/site-packages/flask/helpers.py", line 983, in send_static_file
    cache_timeout=cache_timeout)
  File "/home/eddjou/.local/lib/python2.7/site-packages/flask/helpers.py", line 720, in send_from_directory
    return send_file(filename, **options)
  File "/home/eddjou/.local/lib/python2.7/site-packages/flask/helpers.py", line 595, in send_file
    file = open(filename, 'rb')
IOError: [Errno 13] Permission denied: u'/home/eddjou/exp-psiturk-example/static/js/task.js'
2019-08-05 08:25:25,726 Exception on /static/js/task.js [GET]
Traceback (most recent call last):
  File "/home/eddjou/.local/lib/python2.7/site-packages/flask/app.py", line 2311, in wsgi_app
    response = self.full_dispatch_request()
  File "/home/eddjou/.local/lib/python2.7/site-packages/flask/app.py", line 1834, in full_dispatch_request
    rv = self.handle_user_exception(e)
  File "/home/eddjou/.local/lib/python2.7/site-packages/flask/app.py", line 1737, in handle_user_exception
    reraise(exc_type, exc_value, tb)
  File "/home/eddjou/.local/lib/python2.7/site-packages/flask/app.py", line 1832, in full_dispatch_request
    rv = self.dispatch_request()
  File "/home/eddjou/.local/lib/python2.7/site-packages/flask/app.py", line 1818, in dispatch_request
    return self.view_functions[rule.endpoint](**req.view_args)
  File "/home/eddjou/.local/lib/python2.7/site-packages/flask/helpers.py", line 983, in send_static_file
    cache_timeout=cache_timeout)
  File "/home/eddjou/.local/lib/python2.7/site-packages/flask/helpers.py", line 720, in send_from_directory
    return send_file(filename, **options)
  File "/home/eddjou/.local/lib/python2.7/site-packages/flask/helpers.py", line 595, in send_file
    file = open(filename, 'rb')
IOError: [Errno 13] Permission denied: u'/home/eddjou/exp-psiturk-example/static/js/task.js'
2019-08-05 08:25:26,049 Exception on /static/js/task.js [GET]
Traceback (most recent call last):
  File "/home/eddjou/.local/lib/python2.7/site-packages/flask/app.py", line 2311, in wsgi_app
    response = self.full_dispatch_request()
  File "/home/eddjou/.local/lib/python2.7/site-packages/flask/app.py", line 1834, in full_dispatch_request
    rv = self.handle_user_exception(e)
  File "/home/eddjou/.local/lib/python2.7/site-packages/flask/app.py", line 1737, in handle_user_exception
    reraise(exc_type, exc_value, tb)
  File "/home/eddjou/.local/lib/python2.7/site-packages/flask/app.py", line 1832, in full_dispatch_request
    rv = self.dispatch_request()
  File "/home/eddjou/.local/lib/python2.7/site-packages/flask/app.py", line 1818, in dispatch_request
    return self.view_functions[rule.endpoint](**req.view_args)
  File "/home/eddjou/.local/lib/python2.7/site-packages/flask/helpers.py", line 983, in send_static_file
    cache_timeout=cache_timeout)
  File "/home/eddjou/.local/lib/python2.7/site-packages/flask/helpers.py", line 720, in send_from_directory
    return send_file(filename, **options)
  File "/home/eddjou/.local/lib/python2.7/site-packages/flask/helpers.py", line 595, in send_file
    file = open(filename, 'rb')
IOError: [Errno 13] Permission denied: u'/home/eddjou/exp-psiturk-example/static/js/task.js'
2019-08-06 09:13:27,943 Exception on /sync/debug27FV8R:debug9FMYN1 [PUT]
Traceback (most recent call last):
  File "/home/eddjou/.local/lib/python2.7/site-packages/flask/app.py", line 2311, in wsgi_app
    response = self.full_dispatch_request()
  File "/home/eddjou/.local/lib/python2.7/site-packages/flask/app.py", line 1834, in full_dispatch_request
    rv = self.handle_user_exception(e)
  File "/home/eddjou/.local/lib/python2.7/site-packages/flask/app.py", line 1737, in handle_user_exception
    reraise(exc_type, exc_value, tb)
  File "/home/eddjou/.local/lib/python2.7/site-packages/flask/app.py", line 1832, in full_dispatch_request
    rv = self.dispatch_request()
  File "/home/eddjou/.local/lib/python2.7/site-packages/flask/app.py", line 1818, in dispatch_request
    return self.view_functions[rule.endpoint](**req.view_args)
  File "/home/eddjou/.local/lib/python2.7/site-packages/psiturk/experiment.py", line 591, in update
    db_session.commit()
  File "/home/eddjou/.local/lib/python2.7/site-packages/sqlalchemy/orm/scoping.py", line 162, in do
    return getattr(self.registry(), name)(*args, **kwargs)
  File "/home/eddjou/.local/lib/python2.7/site-packages/sqlalchemy/orm/session.py", line 1027, in commit
    self.transaction.commit()
  File "/home/eddjou/.local/lib/python2.7/site-packages/sqlalchemy/orm/session.py", line 498, in commit
    t[1].commit()
  File "/home/eddjou/.local/lib/python2.7/site-packages/sqlalchemy/engine/base.py", line 1716, in commit
    self._do_commit()
  File "/home/eddjou/.local/lib/python2.7/site-packages/sqlalchemy/engine/base.py", line 1747, in _do_commit
    self.connection._commit_impl()
  File "/home/eddjou/.local/lib/python2.7/site-packages/sqlalchemy/engine/base.py", line 763, in _commit_impl
    self._handle_dbapi_exception(e, None, None, None, None)
  File "/home/eddjou/.local/lib/python2.7/site-packages/sqlalchemy/engine/base.py", line 1466, in _handle_dbapi_exception
    util.raise_from_cause(sqlalchemy_exception, exc_info)
  File "/home/eddjou/.local/lib/python2.7/site-packages/sqlalchemy/util/compat.py", line 399, in raise_from_cause
    reraise(type(exception), exception, tb=exc_tb, cause=cause)
  File "/home/eddjou/.local/lib/python2.7/site-packages/sqlalchemy/engine/base.py", line 761, in _commit_impl
    self.engine.dialect.do_commit(self.connection)
  File "/home/eddjou/.local/lib/python2.7/site-packages/sqlalchemy/engine/default.py", line 503, in do_commit
    dbapi_connection.commit()
OperationalError: (sqlite3.OperationalError) disk I/O error
(Background on this error at: http://sqlalche.me/e/e3q8)
2019-08-06 09:13:27,960 Exception during reset or similar
Traceback (most recent call last):
  File "/home/eddjou/.local/lib/python2.7/site-packages/sqlalchemy/pool/base.py", line 680, in _finalize_fairy
    fairy._reset(pool)
  File "/home/eddjou/.local/lib/python2.7/site-packages/sqlalchemy/pool/base.py", line 867, in _reset
    pool._dialect.do_rollback(self)
  File "/home/eddjou/.local/lib/python2.7/site-packages/sqlalchemy/engine/default.py", line 500, in do_rollback
    dbapi_connection.rollback()
OperationalError: cannot rollback - no transaction is active
2019-08-06 09:22:43,658 Exception on /sync/debugL3MSS3:debug2XKO3Z [PUT]
Traceback (most recent call last):
  File "/home/eddjou/.local/lib/python2.7/site-packages/flask/app.py", line 2311, in wsgi_app
    response = self.full_dispatch_request()
  File "/home/eddjou/.local/lib/python2.7/site-packages/flask/app.py", line 1834, in full_dispatch_request
    rv = self.handle_user_exception(e)
  File "/home/eddjou/.local/lib/python2.7/site-packages/flask/app.py", line 1737, in handle_user_exception
    reraise(exc_type, exc_value, tb)
  File "/home/eddjou/.local/lib/python2.7/site-packages/flask/app.py", line 1832, in full_dispatch_request
    rv = self.dispatch_request()
  File "/home/eddjou/.local/lib/python2.7/site-packages/flask/app.py", line 1818, in dispatch_request
    return self.view_functions[rule.endpoint](**req.view_args)
  File "/home/eddjou/.local/lib/python2.7/site-packages/psiturk/experiment.py", line 591, in update
    db_session.commit()
  File "/home/eddjou/.local/lib/python2.7/site-packages/sqlalchemy/orm/scoping.py", line 162, in do
    return getattr(self.registry(), name)(*args, **kwargs)
  File "/home/eddjou/.local/lib/python2.7/site-packages/sqlalchemy/orm/session.py", line 1027, in commit
    self.transaction.commit()
  File "/home/eddjou/.local/lib/python2.7/site-packages/sqlalchemy/orm/session.py", line 498, in commit
    t[1].commit()
  File "/home/eddjou/.local/lib/python2.7/site-packages/sqlalchemy/engine/base.py", line 1716, in commit
    self._do_commit()
  File "/home/eddjou/.local/lib/python2.7/site-packages/sqlalchemy/engine/base.py", line 1747, in _do_commit
    self.connection._commit_impl()
  File "/home/eddjou/.local/lib/python2.7/site-packages/sqlalchemy/engine/base.py", line 763, in _commit_impl
    self._handle_dbapi_exception(e, None, None, None, None)
  File "/home/eddjou/.local/lib/python2.7/site-packages/sqlalchemy/engine/base.py", line 1466, in _handle_dbapi_exception
    util.raise_from_cause(sqlalchemy_exception, exc_info)
  File "/home/eddjou/.local/lib/python2.7/site-packages/sqlalchemy/util/compat.py", line 399, in raise_from_cause
    reraise(type(exception), exception, tb=exc_tb, cause=cause)
  File "/home/eddjou/.local/lib/python2.7/site-packages/sqlalchemy/engine/base.py", line 761, in _commit_impl
    self.engine.dialect.do_commit(self.connection)
  File "/home/eddjou/.local/lib/python2.7/site-packages/sqlalchemy/engine/default.py", line 503, in do_commit
    dbapi_connection.commit()
OperationalError: (sqlite3.OperationalError) disk I/O error
(Background on this error at: http://sqlalche.me/e/e3q8)
2019-08-06 09:22:43,670 Exception during reset or similar
Traceback (most recent call last):
  File "/home/eddjou/.local/lib/python2.7/site-packages/sqlalchemy/pool/base.py", line 680, in _finalize_fairy
    fairy._reset(pool)
  File "/home/eddjou/.local/lib/python2.7/site-packages/sqlalchemy/pool/base.py", line 867, in _reset
    pool._dialect.do_rollback(self)
  File "/home/eddjou/.local/lib/python2.7/site-packages/sqlalchemy/engine/default.py", line 500, in do_rollback
    dbapi_connection.rollback()
OperationalError: cannot rollback - no transaction is active
2019-08-06 10:23:48,466 DB error: Unique user not found.
2019-08-06 10:23:48,468 Exception during reset or similar
Traceback (most recent call last):
  File "/home/eddjou/.local/lib/python2.7/site-packages/sqlalchemy/pool/base.py", line 680, in _finalize_fairy
    fairy._reset(pool)
  File "/home/eddjou/.local/lib/python2.7/site-packages/sqlalchemy/pool/base.py", line 867, in _reset
    pool._dialect.do_rollback(self)
  File "/home/eddjou/.local/lib/python2.7/site-packages/sqlalchemy/engine/default.py", line 500, in do_rollback
    dbapi_connection.rollback()
OperationalError: cannot rollback - no transaction is active
